Workbook

Sheet Calendar
A1: Subscriber Id | B1: Member Id | C1: Identification | D1: Name | E1: Arrived | F1: Created | G1: Updated | H1: Date of Birth | I1: First name | J1: Last name | K1: Active | L1: Status | M1: Phone | N1: Whatsapp link | O1: Email | P1: Birthdate | Q1: Address | R1: First Name | S1: Last Name | T1: Phone Number | U1: Payment status | V1: Amount paid | W1: Refund | X1: Tickets | Y1: Scanner Enabled | Z1: Custom Status | AA1: Admin comment | AB1: Gender | AC1: RSVP | AD1: Registration notification | AE1: Join origin | AF1: Attachments | AG1: [user] Which age group do you belong to? (Optional) | AH1: Calendar
A2: 67229 | B2: 64017 | D2: Precious Otis | E2: FALSE | F2: 01/17/2026 8:12 AM | G2: 01/17/2026 8:12 AM | H2: 05/12/1998 8:00 PM | I2: Precious | J2: Otis | K2: TRUE | L2: Active | M2: 13057613295 | N2: https://wa.me/13057613295 | O2: Precious_otis@yahoo.com | Q2: 1315 nw 172 terrace | R2: Precious | S2: Otis | T2: 3057613295 | U2: none | V2: 0.00 | W2: 0.00 | X2: 1 | Y2: FALSE | AC2: not_responded | AD2: TRUE | AE2: web_app | AH2: YES | AI2: =VLOOKUP(O2,SQL!$E$1:$G$62,3,0) -> Calendar
A3: 67228 | B3: 64016 | D3: Elan Doeman | E3: FALSE | F3: 01/17/2026 7:49 AM | G3: 01/17/2026 7:49 AM | H3: 02/02/1994 7:00 PM | I3: Elan | J3: Doeman | K3: TRUE | L3: Active | M3: 17865373662 | N3: https://wa.me/17865373662 | O3: elandoeman19@gmail.com | Q3: 105 Royal Park Dr | R3: Elan | S3: Doeman | T3: 7865373662 | U3: none | V3: 0.00 | W3: 0.00 | X3: 1 | Y3: FALSE | AC3: not_responded | AD3: TRUE | AE3: web_app | AG3: 25-34 | AH3: YES | AI3: =VLOOKUP(O3,SQL!$E$1:$G$62,3,0) -> Calendar
A4: 67223 | B4: 64011 | D4: chris addison | E4: FALSE | F4: 01/16/2026 11:00 PM | G4: 01/16/2026 11:00 PM | H4: 09/26/1994 8:00 PM | I4: chris | J4: addison | K4: TRUE | L4: Active | M4: 19544151592 | N4: https://wa.me/19544151592 | O4: 13chrisaddison@gmail.com | Q4: 5609 Blueberry Ct Lauderhill, Fl 33313 | R4: Chris | S4: Addison | T4: 9544151592 | U4: none | V4: 0.00 | W4: 0.00 | X4: 1 | Y4: FALSE | AC4: not_responded | AD4: TRUE | AE4: web_app | AH4: YES | AI4: =VLOOKUP(O4,SQL!$E$1:$G$62,3,0) -> Calendar
A5: 67221 | B5: 64006 | D5: BLOSSOM BACCHUS | E5: FALSE | F5: 01/16/2026 7:59 PM | G5: 01/16/2026 7:59 PM | H5: 09/03/1972 8:00 PM | I5: BLOSSOM | J5: BACCHUS | K5: TRUE | L5: Active | M5: 13478167646 | N5: https://wa.me/13478167646 | O5: queenblossy@gmail.com | Q5: 7610 Westwood Dr 101 | R5: Blossom | S5: Bacchus | T5: 3478167646 | U5: none | V5: 0.00 | W5: 0.00 | X5: 1 | Y5: FALSE | AC5: not_responded | AD5: TRUE | AE5: web_app | AG5: 45-54 | AH5: YES | AI5: =VLOOKUP(O5,SQL!$E$1:$G$62,3,0) -> Calendar
A6: 67209 | B6: 63996 | D6: Vee Francois | E6: FALSE | F6: 01/16/2026 5:22 PM | G6: 01/16/2026 5:22 PM | H6: 12/27/2001 7:00 PM | I6: Vee | J6: Francois | K6: TRUE | L6: Active | M6: 19546432117 | N6: https://wa.me/19546432117 | O6: Varenskafrancois@icloud.com | Q6: 3549 Nw 34 St | R6: Varenska | S6: Francois | T6: 9546432117 | U6: none | V6: 0.00 | W6: 0.00 | X6: 1 | Y6: FALSE | AC6: not_responded | AD6: TRUE | AE6: web_app | AG6: 18-24 | AH6: YES | AI6: =VLOOKUP(O6,SQL!$E$1:$G$62,3,0) -> #N/A
A7: 67176 | B7: 63981 | D7: James (Jesse) Antonelli | E7: FALSE | F7: 01/16/2026 12:13 PM | G7: 01/16/2026 12:13 PM | H7: 09/06/1963 7:30 AM | I7: James (Jesse) | J7: Antonelli | K7: TRUE | L7: Active | M7: 19542639644 | N7: https://wa.me/19542639644 | O7: thatjessejames@comcast.net | Q7: 6191 LAUREL LN | R7: James (Jesse) | S7: Antonelli | T7: 9542639644 | U7: none | V7: 0.00 | W7: 0.00 | X7: 1 | Y7: FALSE | AC7: not_responded | AD7: TRUE | AE7: web_app | AG7: 55+ | AH7: YES | AI7: =VLOOKUP(O7,SQL!$E$1:$G$62,3,0) -> Calendar
A8: 67171 | B8: 63970 | D8: Paula Salgar | E8: FALSE | F8: 01/16/2026 10:43 AM | G8: 01/16/2026 10:43 AM | H8: 07/26/1987 8:00 PM | I8: Paula | J8: Salgar | K8: TRUE | L8: Active | M8: 19546518555 | N8: https://wa.me/19546518555 | O8: PAULA@BRIGHTOLOGYLIGHTING.COM | Q8: 7920 nw 89th ave | R8: Paula | S8: Salgar | T8: 9546518555 | U8: none | V8: 0.00 | W8: 0.00 | X8: 1 | Y8: FALSE | AC8: not_responded | AD8: TRUE | AE8: web_app | AG8: 35-44 | AH8: YES | AI8: =VLOOKUP(O8,SQL!$E$1:$G$62,3,0) -> Calendar
A9: 67118 | B9: 63917 | D9: Fabio Edwards | E9: FALSE | F9: 01/15/2026 2:52 PM | G9: 01/15/2026 2:52 PM | H9: 12/25/2025 7:00 PM | I9: Fabio | J9: Edwards | K9: TRUE | L9: Active | M9: 17542421276 | N9: https://wa.me/17542421276 | O9: fabioe1986@gmail.com | Q9: 7747 NW 79th St | R9: Fabio | S9: Edwards | T9: 7542421276 | U9: none | V9: 0.00 | W9: 0.00 | X9: 1 | Y9: FALSE | AC9: not_responded | AD9: TRUE | AE9: web_app | AG9: 35-44 | AH9: YES | AI9: =VLOOKUP(O9,SQL!$E$1:$G$62,3,0) -> Calendar
A10: 67072 | B10: 63874 | D10: Dee Major | E10: FALSE | F10: 01/15/2026 9:53 AM | G10: 01/15/2026 9:53 AM | H10: 06/12/1996 8:00 PM | I10: Dee | J10: Major | K10: TRUE | L10: Active | M10: 13054962504 | N10: https://wa.me/13054962504 | O10: d_smithmajor96@yahoo.com | Q10: 610 Sw 147th Ter | R10: Dee | S10: Major | T10: 3054962504 | U10: none | V10: 0.00 | W10: 0.00 | X10: 1 | Y10: FALSE | AC10: not_responded | AD10: TRUE | AE10: web_app | AG10: 25-34 | AH10: YES | AI10: =VLOOKUP(O10,SQL!$E$1:$G$62,3,0) -> Calendar
A11: 67071 | B11: 63873 | D11: Krishna Gelin | E11: FALSE | F11: 01/15/2026 9:47 AM | G11: 01/15/2026 9:47 AM | H11: 01/03/2020 9:15 AM | I11: Krishna | J11: Gelin | K11: TRUE | L11: Active | M11: 13527927617 | N11: https://wa.me/13527927617 | O11: gelin.krishna@yahoo.com | Q11: 5429 NW 50th Ct Coconut Creek Fl | R11: Krishna | S11: Gelin | T11: 3527927617 | U11: none | V11: 0.00 | W11: 0.00 | X11: 1 | Y11: FALSE | AC11: not_responded | AD11: TRUE | AE11: web_app | AG11: 25-34 | AH11: YES | AI11: =VLOOKUP(O11,SQL!$E$1:$G$62,3,0) -> Calendar
A12: 67068 | B12: 63868 | D12: Kaelyn Edwards | E12: FALSE | F12: 01/14/2026 11:42 PM | G12: 01/14/2026 11:42 PM | H12: 01/06/2010 7:00 AM | I12: Kaelyn | J12: Edwards | K12: TRUE | L12: Active | M12: 17542440057 | N12: https://wa.me/17542440057 | O12: kaelynedwards3@gmail.com | Q12: 5528 Northwest 90th Avenue | R12: Kaelyn | S12: Edwards | T12: 7542440057 | U12: none | V12: 0.00 | W12: 0.00 | X12: 1 | Y12: FALSE | AC12: not_responded | AD12: TRUE | AE12: web_app | AH12: YES | AI12: =VLOOKUP(O12,SQL!$E$1:$G$62,3,0) -> Calendar
A13: 66997 | B13: 39216 | D13: Denise Collins | E13: FALSE | F13: 01/13/2026 6:31 PM | G13: 01/13/2026 6:31 PM | H13: 03/03/2026 7:00 PM | I13: Denise | J13: Collins | K13: TRUE | L13: Active | M13: 19548992891 | N13: https://wa.me/19548992891 | O13: nese6@comcast.net | Q13: 6425 Pinehurst Circle W | R13: Denise | S13: Collins | T13: 9548992891 | U13: none | V13: 0.00 | W13: 0.00 | X13: 1 | Y13: FALSE | AC13: not_responded | AD13: TRUE | AE13: web_app | AG13: 55+ | AH13: YES | AI13: =VLOOKUP(O13,SQL!$E$1:$G$62,3,0) -> Calendar
A14: 66929 | B14: 63738 | D14: Leila Isaacs | E14: FALSE | F14: 01/12/2026 9:05 PM | G14: 01/13/2026 6:04 AM | H14: 01/05/2026 7:00 PM | I14: Leila | J14: Isaacs | K14: FALSE | L14: Member Unsubscribed | M14: 19178373410 | N14: https://wa.me/19178373410 | O14: Leilaisaacs11@gmail.com | Q14: 7754 Granville St | R14: Leila | S14: Isaacs | T14: 9178373410 | U14: none | V14: 0.00 | W14: 0.00 | X14: 1 | Y14: FALSE | AC14: not_responded | AD14: TRUE | AE14: web_app | AG14: 55+ | AH14: YES | AI14: =VLOOKUP(O14,SQL!$E$1:$G$62,3,0) -> Calendar
A15: 66941 | B15: 63748 | D15: Tammy Delgado | E15: FALSE | F15: 01/13/2026 12:33 AM | G15: 01/13/2026 12:33 AM | H15: 01/26/2026 7:00 PM | I15: Tammy | J15: Delgado | K15: TRUE | L15: Active | M15: 19548299189 | N15: https://wa.me/19548299189 | O15: Tvtams@gmail.com | Q15: 7962 Exeter Circle East Tamarac FL 33321 | R15: Tammy | S15: Delgado | T15: 9548299189 | U15: none | V15: 0.00 | W15: 0.00 | X15: 1 | Y15: FALSE | AC15: not_responded | AD15: TRUE | AE15: web_app | AG15: 55+ | AH15: YES | AI15: =VLOOKUP(O15,SQL!$E$1:$G$62,3,0) -> Calendar
A16: 66933 | B16: 63741 | D16: Melody Moore | E16: FALSE | F16: 01/12/2026 9:24 PM | G16: 01/12/2026 9:24 PM | H16: 12/09/1969 8:15 PM | I16: Melody | J16: Moore | K16: TRUE | L16: Active | M16: 19544465736 | N16: https://wa.me/19544465736 | O16: Msmalibu31@gmail.com | Q16: 7300 NW 54th Ct | R16: Melody | S16: Moore | T16: 9544465736 | U16: none | V16: 0.00 | W16: 0.00 | X16: 1 | Y16: FALSE | AC16: not_responded | AD16: TRUE | AE16: web_app | AG16: 55+ | AH16: YES | AI16: =VLOOKUP(O16,SQL!$E$1:$G$62,3,0) -> Calendar
A17: 66915 | B17: 63729 | D17: Davina Rowe | E17: FALSE | F17: 01/12/2026 6:28 PM | G17: 01/12/2026 6:28 PM | H17: 09/30/1982 8:00 PM | I17: Davina | J17: Rowe | K17: TRUE | L17: Active | M17: 19545521016 | N17: https://wa.me/19545521016 | O17: Davinarowesmith@gmail.com | Q17: 7960 Northwest 50th Street | R17: Davina | S17: Rowe | T17: 9545521016 | U17: none | V17: 0.00 | W17: 0.00 | X17: 1 | Y17: FALSE | AC17: not_responded | AD17: TRUE | AE17: web_app | AG17: 45-54 | AH17: YES | AI17: =VLOOKUP(O17,SQL!$E$1:$G$62,3,0) -> Calendar
A18: 66914 | B18: 63728 | D18: Janice Dias | E18: FALSE | F18: 01/12/2026 6:15 PM | G18: 01/12/2026 6:15 PM | H18: 06/28/1987 8:00 PM | I18: Janice | J18: Dias | K18: TRUE | L18: Active | M18: 19546083788 | N18: https://wa.me/19546083788 | O18: jmdias87@Gmail.com | Q18: 6840 nw 46th court | R18: Janice | S18: Dias | T18: 9546083788 | U18: none | V18: 0.00 | W18: 0.00 | X18: 1 | Y18: FALSE | AC18: not_responded | AD18: TRUE | AE18: web_app | AG18: 35-44 | AH18: YES | AI18: =VLOOKUP(O18,SQL!$E$1:$G$62,3,0) -> Calendar
A19: 66909 | B19: 63721 | D19: Jon Edwards | E19: FALSE | F19: 01/12/2026 3:54 PM | G19: 01/12/2026 3:54 PM | H19: 01/10/1974 2:00 AM | I19: Jon | J19: Edwards | K19: TRUE | L19: Active | M19: 19543106454 | N19: https://wa.me/19543106454 | O19: davierre@msn.com | Q19: 5528 Northwest 90th Avenue | R19: Jonath | S19: Edwards | T19: 9543106454 | U19: none | V19: 0.00 | W19: 0.00 | X19: 1 | Y19: FALSE | AC19: not_responded | AD19: TRUE | AE19: web_app | AG19: 45-54 | AH19: YES | AI19: =VLOOKUP(O19,SQL!$E$1:$G$62,3,0) -> Calendar
A20: 66908 | B20: 63720 | D20: Duon's pathways | E20: FALSE | F20: 01/12/2026 3:37 PM | G20: 01/12/2026 3:37 PM | H20: 09/07/1997 8:00 PM | I20: Duon's | J20: pathways | K20: TRUE | L20: Active | M20: 13473518575 | N20: https://wa.me/13473518575 | O20: Dpenso1@outlook.com | Q20: 8206 NW 104th ave | R20: Duo | S20: Penso | T20: 3473518575 | U20: none | V20: 0.00 | W20: 0.00 | X20: 1 | Y20: FALSE | AC20: not_responded | AD20: TRUE | AE20: web_app | AH20: YES | AI20: =VLOOKUP(O20,SQL!$E$1:$G$62,3,0) -> Calendar
A21: 66907 | B21: 63718 | D21: Cedric Francoeur | E21: FALSE | F21: 01/12/2026 3:35 PM | G21: 01/12/2026 3:35 PM | H21: 09/09/1991 8:00 PM | I21: Cedric | J21: Francoeur | K21: TRUE | L21: Active | M21: 13059044778 | N21: https://wa.me/13059044778 | O21: Francoeurp1@gmail.com | Q21: 7021 woodmont way | R21: Cedric | S21: Francoeur | T21: 3059044778 | U21: none | V21: 0.00 | W21: 0.00 | X21: 1 | Y21: FALSE | AC21: not_responded | AD21: TRUE | AE21: web_app | AG21: 25-34 | AH21: YES | AI21: =VLOOKUP(O21,SQL!$E$1:$G$62,3,0) -> Calendar
A22: 66906 | B22: 63719 | D22: Bianca Hardy | E22: FALSE | F22: 01/12/2026 3:32 PM | G22: 01/12/2026 3:32 PM | H22: 01/28/1990 7:00 PM | I22: Bianca | J22: Hardy | K22: TRUE | L22: Active | M22: 19547322921 | N22: https://wa.me/19547322921 | O22: mspinktastiz@yahoo.com | Q22: 9435 W Mcnab Rd #209 Tamarac Fl 33321 | R22: Bianca | S22: Hardy | T22: 9547322921 | U22: none | V22: 0.00 | W22: 0.00 | X22: 1 | Y22: FALSE | AC22: not_responded | AD22: TRUE | AE22: web_app | AG22: 35-44 | AH22: YES | AI22: =VLOOKUP(O22,SQL!$E$1:$G$62,3,0) -> Calendar
A23: 66889 | B23: 63696 | D23: Lu chisha Burris | E23: FALSE | F23: 01/12/2026 12:31 PM | G23: 01/12/2026 12:31 PM | H23: 05/10/1981 8:00 PM | I23: Lu chisha | J23: Burris | K23: TRUE | L23: Active | M23: 19546820453 | N23: https://wa.me/19546820453 | O23: luchburris@yahoo.com | Q23: 8060 N Nob Hill Rd | R23: Luchisha | S23: Phillips | T23: 9546820453 | U23: none | V23: 0.00 | W23: 0.00 | X23: 1 | Y23: FALSE | AC23: not_responded | AD23: TRUE | AE23: web_app | AG23: 35-44 | AH23: YES | AI23: =VLOOKUP(O23,SQL!$E$1:$G$62,3,0) -> Calendar
A24: 66878 | B24: 63684 | D24: Chris Shea | E24: FALSE | F24: 01/12/2026 10:26 AM | G24: 01/12/2026 10:26 AM | H24: 12/09/1955 7:00 PM | I24: Chris | J24: Shea | K24: TRUE | L24: Active | M24: 12522561499 | N24: https://wa.me/12522561499 | O24: vetcycler@yahoo.com | Q24: 11030 Palm Ridge Lane | R24: Chris | S24: Shea | T24: 2522561499 | U24: none | V24: 0.00 | W24: 0.00 | X24: 1 | Y24: FALSE | AC24: not_responded | AD24: TRUE | AE24: web_app | AG24: 55+ | AH24: YES | AI24: =VLOOKUP(O24,SQL!$E$1:$G$62,3,0) -> Calendar
A25: 66841 | B25: 63651 | D25: Maria Martin | E25: FALSE | F25: 01/11/2026 11:42 AM | G25: 01/11/2026 11:42 AM | H25: 10/27/1974 7:00 PM | I25: Maria | J25: Martin | K25: TRUE | L25: Active | M25: 19549077995 | N25: https://wa.me/19549077995 | O25: mariafmartin.28@gmail.com | Q25: 8900 nw 77 ct | R25: Maria | S25: Martin | T25: 9549077995 | U25: none | V25: 0.00 | W25: 0.00 | X25: 1 | Y25: FALSE | AC25: not_responded | AD25: TRUE | AE25: web_app | AG25: 45-54 | AH25: YES | AI25: =VLOOKUP(O25,SQL!$E$1:$G$62,3,0) -> Calendar
A26: 66839 | B26: 63648 | D26: Daniel Herrera | E26: FALSE | F26: 01/11/2026 11:37 AM | G26: 01/11/2026 11:37 AM | H26: 01/13/1975 7:00 PM | I26: Daniel | J26: Herrera | K26: TRUE | L26: Active | M26: 17542327777 | N26: https://wa.me/17542327777 | O26: doherrera1875@gmail.com | Q26: 8900 NW 77th Ct | R26: Daniel | S26: Herrera | T26: 7542327777 | U26: none | V26: 0.00 | W26: 0.00 | X26: 1 | Y26: FALSE | AC26: not_responded | AD26: TRUE | AE26: web_app | AG26: 45-54 | AH26: YES | AI26: =VLOOKUP(O26,SQL!$E$1:$G$62,3,0) -> Calendar
A27: 66836 | B27: 63647 | D27: Hector Batista | E27: FALSE | F27: 01/11/2026 11:23 AM | G27: 01/11/2026 11:23 AM | H27: 02/13/2008 8:00 PM | I27: Hector | J27: Batista | K27: TRUE | L27: Active | M27: 18509022031 | N27: https://wa.me/18509022031 | O27: h.batista102@gmail.com | Q27: 1080 NW 117Ave | R27: Hector | S27: Batista | T27: 8509022031 | U27: none | V27: 0.00 | W27: 0.00 | X27: 1 | Y27: FALSE | AC27: not_responded | AD27: TRUE | AE27: web_app | AG27: 55+ | AH27: YES | AI27: =VLOOKUP(O27,SQL!$E$1:$G$62,3,0) -> Calendar
A28: 66783 | B28: 63613 | D28: Gustavo Hernandez | E28: FALSE | F28: 01/09/2026 9:38 PM | G28: 01/09/2026 9:38 PM | H28: 01/29/1984 7:00 PM | I28: Gustavo | J28: Hernandez | K28: TRUE | L28: Active | M28: 17864395024 | N28: https://wa.me/17864395024 | O28: Gusjhb@gmail.com | Q28: 7050 southgate blvd 101 | R28: Gustavo | S28: Hernandez | T28: 7864395024 | U28: none | V28: 0.00 | W28: 0.00 | X28: 1 | Y28: FALSE | AC28: not_responded | AD28: TRUE | AE28: web_app | AH28: YES | AI28: =VLOOKUP(O28,SQL!$E$1:$G$62,3,0) -> Calendar
A29: 66577 | B29: 63496 | D29: Kenneth Lopez | E29: FALSE | F29: 01/08/2026 2:53 PM | G29: 01/08/2026 2:53 PM | H29: 03/13/1991 7:00 PM | I29: Kenneth | J29: Lopez | K29: TRUE | L29: Active | M29: 17549719418 | N29: https://wa.me/17549719418 | O29: Kenneth.lopez@tamarac.org | Q29: 4025 Carambola Circle North | R29: Kenneth | S29: Lopez | T29: 7549719418 | U29: none | V29: 0.00 | W29: 0.00 | X29: 1 | Y29: FALSE | AC29: not_responded | AD29: TRUE | AE29: web_app | AG29: 35-44 | AH29: YES | AI29: =VLOOKUP(O29,SQL!$E$1:$G$62,3,0) -> Calendar
A30: 66572 | B30: 58245 | D30: Mike Gelin | E30: FALSE | F30: 01/08/2026 2:21 PM | G30: 01/08/2026 2:21 PM | H30: 06/13/2026 1:05 PM | I30: Mike | J30: Gelin | K30: TRUE | L30: Active | M30: 19549130299 | N30: https://wa.me/19549130299 | O30: mike.gelin@gmail.com | Q30: 5901 Abbey Road | R30: Mike | S30: Gelin | T30: 9549130299 | U30: none | V30: 0.00 | W30: 0.00 | X30: 1 | Y30: FALSE | AC30: not_responded | AD30: TRUE | AE30: web_app | AG30: 45-54 | AH30: YES | AI30: =VLOOKUP(O30,SQL!$E$1:$G$62,3,0) -> Calendar
A31: 66551 | B31: 63482 | D31: Brianna Grant | E31: FALSE | F31: 01/08/2026 12:38 PM | G31: 01/08/2026 12:38 PM | H31: 09/12/2026 8:00 PM | I31: Brianna | J31: Grant | K31: TRUE | L31: Active | M31: 14078740744 | N31: https://wa.me/14078740744 | O31: Grant5600@icloud.com | Q31: 5600 nw 55th lane Tamarac | R31: Brianna | S31: Grant | T31: 4078740744 | U31: none | V31: 0.00 | W31: 0.00 | X31: 1 | Y31: FALSE | AC31: not_responded | AD31: TRUE | AE31: web_app | AG31: 25-34 | AH31: YES | AI31: =VLOOKUP(O31,SQL!$E$1:$G$62,3,0) -> Calendar
A32: 66550 | B32: 63480 | D32: Roger Godoy | E32: FALSE | F32: 01/08/2026 12:30 PM | G32: 01/08/2026 12:30 PM | H32: 10/24/1971 8:00 PM | I32: Roger | J32: Godoy | K32: TRUE | L32: Active | M32: 19548644691 | N32: https://wa.me/19548644691 | O32: roriryrare@gmail.com | Q32: 10450 SW 7TH CT APT 114 | R32: Roger | S32: Godoy | T32: 9548644691 | U32: none | V32: 0.00 | W32: 0.00 | X32: 1 | Y32: FALSE | AC32: not_responded | AD32: TRUE | AE32: web_app | AG32: 55+ | AH32: YES | AI32: =VLOOKUP(O32,SQL!$E$1:$G$62,3,0) -> Calendar
A33: 66549 | B33: 63478 | D33: Rita Godoy | E33: FALSE | F33: 01/08/2026 12:26 PM | G33: 01/08/2026 12:26 PM | H33: 08/12/1976 8:00 PM | I33: Rita | J33: Godoy | K33: TRUE | L33: Active | M33: 19548644680 | N33: https://wa.me/19548644680 | O33: roriryra@gmail.com | Q33: 10450 SW 7TH CT APT 114 | R33: Rita | S33: Godoy | T33: 9548644680 | U33: none | V33: 0.00 | W33: 0.00 | X33: 1 | Y33: FALSE | AC33: not_responded | AD33: TRUE | AE33: web_app | AG33: 45-54 | AH33: YES | AI33: =VLOOKUP(O33,SQL!$E$1:$G$62,3,0) -> Calendar
A34: 66545 | B34: 63476 | D34: Michelle Ramis | E34: FALSE | F34: 01/08/2026 11:55 AM | G34: 01/08/2026 11:55 AM | H34: 09/04/1970 8:00 PM | I34: Michelle | J34: Ramis | K34: TRUE | L34: Active | M34: 19544444400 | N34: https://wa.me/19544444400 | O34: Ramism70@yahoo.com | Q34: 6901 SW 1st Court | R34: Michelle | S34: Ramis | T34: 9544444400 | U34: none | V34: 0.00 | W34: 0.00 | X34: 1 | Y34: FALSE | AC34: not_responded | AD34: TRUE | AE34: web_app | AG34: 55+ | AH34: YES | AI34: =VLOOKUP(O34,SQL!$E$1:$G$62,3,0) -> Calendar
A35: 66529 | B35: 63464 | D35: Wendy Olcima | E35: FALSE | F35: 01/08/2026 10:44 AM | G35: 01/08/2026 10:44 AM | H35: 10/08/2025 8:00 PM | I35: Wendy | J35: Olcima | K35: TRUE | L35: Active | M35: 19546554375 | N35: https://wa.me/19546554375 | O35: Wendydolcima@gmail.com | Q35: 2145 cove lake road | R35: Wendy | S35: Olcima | T35: 9546554375 | U35: none | V35: 0.00 | W35: 0.00 | X35: 1 | Y35: FALSE | AC35: not_responded | AD35: TRUE | AE35: web_app | AG35: 35-44 | AH35: YES | AI35: =VLOOKUP(O35,SQL!$E$1:$G$62,3,0) -> #N/A
A36: 66514 | B36: 63451 | D36: Ana Fernandez | E36: FALSE | F36: 01/08/2026 9:42 AM | G36: 01/08/2026 9:42 AM | H36: 10/02/1994 8:00 PM | I36: Ana | J36: Fernandez | K36: TRUE | L36: Active | M36: 19546081595 | N36: https://wa.me/19546081595 | O36: Afernandez_sports@outlook.com | Q36: 5855 N University Dr Tamarac FL 33321 | R36: Ana | S36: Fernandez | T36: 9546081595 | U36: none | V36: 0.00 | W36: 0.00 | X36: 1 | Y36: FALSE | AC36: not_responded | AD36: TRUE | AE36: web_app | AG36: 25-34 | AH36: YES | AI36: =VLOOKUP(O36,SQL!$E$1:$G$62,3,0) -> Calendar
A37: 66513 | B37: 63450 | D37: Daisy | E37: FALSE | F37: 01/08/2026 9:31 AM | G37: 01/08/2026 9:31 AM | H37: 12/18/1988 7:00 PM | I37: Daisy | K37: TRUE | L37: Active | M37: 117864742440 | N37: https://wa.me/117864742440 | O37: Daisha62@gmail.com | Q37: 9294 NW 13 place | R37: Daisha | S37: Thompson | T37: 7864742449 | U37: none | V37: 0.00 | W37: 0.00 | X37: 1 | Y37: FALSE | AC37: not_responded | AD37: TRUE | AE37: web_app | AH37: YES | AI37: =VLOOKUP(O37,SQL!$E$1:$G$62,3,0) -> Calendar
A38: 66454 | B38: 63424 | D38: Natacha S. Chance | E38: FALSE | F38: 01/07/2026 7:54 PM | G38: 01/07/2026 7:54 PM | H38: 03/25/1974 8:00 PM | I38: Natacha | J38: S. Chance | K38: TRUE | L38: Active | M38: 19545880075 | N38: https://wa.me/19545880075 | O38: nsenechance@gmail.com | Q38: 4630 NW 58th Street | R38: Natacha | S38: Sene-Chance | T38: 9545880075 | U38: none | V38: 0.00 | W38: 0.00 | X38: 1 | Y38: FALSE | AC38: not_responded | AD38: TRUE | AE38: web_app | AG38: 45-54 | AH38: YES | AI38: =VLOOKUP(O38,SQL!$E$1:$G$62,3,0) -> Calendar
A39: 66453 | B39: 63421 | D39: Marsha McBain | E39: FALSE | F39: 01/07/2026 7:53 PM | G39: 01/07/2026 7:53 PM | H39: 09/09/1981 8:00 PM | I39: Marsha | J39: McBain | K39: TRUE | L39: Active | M39: 19548565650 | N39: https://wa.me/19548565650 | O39: ms.marshamcbain@gmail.com | Q39: 7370 FLORES WAY | R39: Marsha | S39: McBain | T39: 9548565650 | U39: none | V39: 0.00 | W39: 0.00 | X39: 1 | Y39: FALSE | AC39: not_responded | AD39: TRUE | AE39: web_app | AG39: 35-44 | AH39: YES | AI39: =VLOOKUP(O39,SQL!$E$1:$G$62,3,0) -> Calendar
A40: 66417 | B40: 63393 | D40: Linda Julien | E40: FALSE | F40: 01/07/2026 3:32 PM | G40: 01/07/2026 3:32 PM | H40: 08/28/1980 8:00 PM | I40: Linda | J40: Julien | K40: TRUE | L40: Active | M40: 19542882035 | N40: https://wa.me/19542882035 | O40: smeza@miamigardens-fl.gov | Q40: 18605 NW 27th Ave | R40: Linda | S40: Julien | T40: 9542882035 | U40: none | V40: 0.00 | W40: 0.00 | X40: 1 | Y40: FALSE | AC40: not_responded | AD40: FALSE | AE40: web_app | AH40: YES | AI40: =VLOOKUP(O40,SQL!$E$1:$G$62,3,0) -> Calendar
...

Sheet SQL
A1: First Name | B1: Last Name | C1: dob | D1: Address | E1: Email | F1: Phone | G1: Registration Method
A2: Alastair | B2: Wilmot | C2: 33031 | D2: 5640 NW 58th Lane | E2: Almyuniverse2020@gmail.com | F2: 19546107476 | G2: Calendar
A3: Amadeus | B3: Hills | C3: 38573 | D3: 1300 Sw 125th Ave | E3: notprovided | F3: 17868659503 | G3: Calendar
A4: Amy | B4: Pisani | C4: 27345 | D4: 7980 NW 89th Ave | E4: aap1113@gmail.com | F4: 19548188189 | G4: Calendar
A5: Ana | B5: Fernandez | C5: 34609 | D5: 5855 N University Dr Tamarac FL 33321 | E5: Afernandez_sports@outlook.com | F5: 19546081595 | G5: Calendar
A6: Bianca | B6: Hardy | C6: 32901 | D6: 9435 W Mcnab Rd #209 Tamarac Fl 33321 | E6: mspinktastiz@yahoo.com | F6: 19547322921 | G6: Calendar
A7: BLOSSOM | B7: BACCHUS | C7: 26545 | D7: 7610 Westwood Dr 101 | E7: queenblossy@gmail.com | F7: 17868659503 | G7: Calendar
A8: Brianna | B8: Grant | C8: 46277 | D8: 5600 nw 55th lane Tamarac | E8: Grant5600@icloud.com | F8: 14078740744 | G8: Calendar | K8: Registration Method
A9: Cedric | B9: Francoeur | C9: 33490 | D9: 7021 woodmont way | E9: Francoeurp1@gmail.com | F9: 13059044778 | G9: Calendar | K9: Calendar | L9: Link | M9: TOTAL
A10: Chris | B10: Shea | C10: 20432 | D10: 11030 Palm Ridge Lane | E10: vetcycler@yahoo.com | F10: 12522561499 | G10: Calendar | K10: =COUNTIF(G1:G100, "Calendar") -> 60 | L10: =COUNTIF(G1:G100, "Link") -> 5 | M10: =K10+L10 -> 65
A11: chris | B11: addison | C11: 09/26/1994 8:00 PM | D11: 5609 Blueberry Ct Lauderhill, Fl 33313 | E11: 13chrisaddison@gmail.com | F11: 19544151592 | G11: Calendar
A12: Christina | B12: Francois | C12: 32321 | D12: 8011 NW 71st Ct | E12: Tina.francois28@gmail.com | F12: 17863972419 | G12: Calendar
A13: Daisy | C13: 32495 | D13: 9294 NW 13 place | E13: Daisha62@gmail.com | F13: 117864742440 | G13: Calendar
A14: Daniel | B14: Herrera | C14: 27407 | D14: 8900 NW 77th Ct | E14: doherrera1875@gmail.com | F14: 17542327777 | G14: Calendar
A15: Davina | B15: Rowe | C15: 30224 | D15: 7960 Northwest 50th Street | E15: Davinarowesmith@gmail.com | F15: 19545521016 | G15: Calendar
A16: Dee | B16: Major | C16: 35228 | D16: 610 Sw 147th Ter | E16: d_smithmajor96@yahoo.com | F16: 13054962504 | G16: Calendar
A17: Denise | B17: Collins | C17: 46084 | D17: 6425 Pinehurst Circle W | E17: nese6@comcast.net | F17: 19548992891 | G17: Calendar
A18: Duon's | B18: pathways | C18: 35680 | D18: 8206 NW 104th ave | E18: Dpenso1@outlook.com | F18: 13473518575 | G18: Calendar
A19: Elan | B19: Doeman | C19: 34368 | D19: 105 royal park dr apt 1c Oakland park fl 33309 | E19: elandoeman19@gmail.com | F19: 7865373662 | G19: Calendar
A20: Elizabeth | B20: Moise | C20: 37420 | D20: 8724 NW 83rd St | E20: moise12@mail.broward.edu | F20: 19542988766 | G20: Calendar
A21: Fabio | B21: Edwards | C21: 46016 | D21: 7747 NW 79th St | E21: fabioe1986@gmail.com | F21: 17542421276 | G21: Calendar
A22: Gloria | B22: Dziamalek | C22: 23309 | D22: 8000 Hampton blvd | E22: begloe1025@hotmail.com | F22: 19542983147 | G22: Calendar
A23: Gustavo | B23: Hernandez | C23: 30710 | D23: 7050 southgate blvd 101 | E23: Gusjhb@gmail.com | F23: 17864395024 | G23: Calendar
A24: Hector | B24: Batista | C24: 39491 | D24: 1080 NW 117Ave | E24: h.batista102@gmail.com | F24: 18509022031 | G24: Calendar
A25: Info | B25: @onestop | C25: 30018 | D25: 4768 W. Commercial blvd Tamarac FL 33319 | E25: Info@onestop4printing.com | F25: 19542573000 | G25: Calendar
... A27: Janice | B27: Dias | C27: 31956 | D27: 6840 nw 46th court | E27: jmdias87@Gmail.com | F27: 19546083788 | G27: Calendar
A28: Jennifer | B28: Leslie | C28: 24715 | D28: 8030 NW 96 Terrace | E28: leslie3j@yahoo.com | G28: Calendar
A29: JesseJames | B29: Antonelli | C29: 46039 | D29: 6191 Laurel Lane | E29: thatjessejames@comcast.net | F29: 9542639644 | G29: Calendar
A30: Jhoanny | B30: Herrera | C30: 32090 | D30: 4217 Nw 109th Terrace | E30: jhoannyh171@gmail.com | F30: 19542285756 | G30: Calendar
A31: Jon | B31: Edwards | C31: 27039 | D31: 5528 Northwest 90th Avenue | E31: davierre@msn.com | F31: 19543106454 | G31: Calendar
A32: Kaelyn | B32: Edwards | C32: 40184 | D32: 5528 Northwest 90th Avenue | E32: kaelynedwards3@gmail.com | F32: 17542440057 | G32: Calendar
A33: Katherine | B33: Montes | C33: 29409 | D33: 7856 Catalina Circle | E33: Katmontes80@gmail.com | F33: 19549909669 | G33: Calendar
A34: Kenneth | B34: Lopez | C34: 33310 | D34: 4025 Carambola Circle North | E34: Kenneth.lopez@tamarac.org | F34: 17549719418 | G34: Calendar
A35: Krishna | B35: Gelin | C35: 43833 | D35: 5429 NW 50th Ct Coconut Creek Fl | E35: gelin.krishna@yahoo.com | F35: 13527927617 | G35: Calendar
A36: La | B36: Nena | C36: 46022 | D36: 8607 NW 59 Ct | E36: msphunk77@gmail.com | F36: 9546087832 | G36: Calendar
A37: Leila | B37: Isaacs | C37: 46027 | D37: 7754 Granville St | E37: Leilaisaacs11@gmail.com | F37: 19178373410 | G37: Calendar
A38: Lex | B38: Pierre louis | C38: 30758 | D38: Lex@Lexpromotions.com | E38: lex@lexpromotions.com | F38: 3056329360 | G38: Link
A39: leyssa | B39: JeanBaptiste | C39: 33003 | D39: 9319 Wedgewood Dr | E39: leyssa.jb@gmail.com | F39: 13057530953 | G39: Calendar
A40: Liana | B40: Grant | C40: 25297 | D40: 5723 nw 87th ave | E40: Whitehair05@gmail.com | F40: 19542436914 | G40: Calendar
... A52: Omar | B52: Outar | C52: 34791 | D52: 400 sw 75th ave north lauderdale fl 33068 | E52: outar425@gmail.com | F52: 9549015560 | G52: Link
...
